Workbook

Sheet Synthèse & Performance
B2: AL BARID BANK
B3: Portail de Suivi de la Qualité Client - Centre de Relations Clients
B4: Performance des Écoutes (Pondération : 70% Fond / 30% Forme)
B6: SYNTHÈSE DES AUDITS QUALITÉ
B8: TOTAL AUDITS RÉALISÉS | C8: MOYENNE GLOBALE DU CENTRE | D8: MOYENNE APPELS ENTRANTS (AE) | E8: MOYENNE APPELS SORTANTS (AS) | F8: TAUX DE CONFORMITÉ | G8: SEMAINE ACTUELLE (REF)
B9: =COUNT('Historique AE AS'!$I$4:$I$123) | C9: =IFERROR(AVERAGE('Historique AE AS'!$I$4:$I$123),"") | D9: =C13 | E9: =F13 | F9: =IF($B$9=0,"",COUNTIF('Historique AE AS'!$J$4:$J$123,"Objectif Atteint")/$B$9) | G9: =_xlfn.ISOWEEKNUM(TODAY())
B11: Moyenne Globale AE | E11: Moyenne Globale AS
B12: APPEL ENTRANT (AE) | E12: APPEL SORTANT (AS)
B13: SCORE MOYEN GLOBAL | C13: =IFERROR(AVERAGEIFS('Historique AE AS'!$I$4:$I$123,'Historique AE AS'!$D$4:$D$123,"AE"),"") | D13: ="Cible : ≥ "&TEXT('KPI Agents'!$E$5,"0.0%") | E13: SCORE MOYEN GLOBAL | F13: =IFERROR(AVERAGEIFS('Historique AE AS'!$I$4:$I$123,'Historique AE AS'!$D$4:$D$123,"AS"),"") | G13: ="Cible : ≥ "&TEXT('KPI Agents'!$E$5,"0.0%")
B14: Moyenne FOND (70%) | C14: =IFERROR(AVERAGEIFS('Historique AE AS'!$G$4:$G$123,'Historique AE AS'!$D$4:$D$123,"AE"),"") | D14: Poids : 70% | E14: Moyenne FOND (70%) | F14: =IFERROR(AVERAGEIFS('Historique AE AS'!$G$4:$G$123,'Historique AE AS'!$D$4:$D$123,"AS"),"") | G14: Poids : 70%
B15: Moyenne FORME (30%) | C15: =IFERROR(AVERAGEIFS('Historique AE AS'!$H$4:$H$123,'Historique AE AS'!$D$4:$D$123,"AE"),"") | D15: Poids : 30% | E15: Moyenne FORME (30%) | F15: =IFERROR(AVERAGEIFS('Historique AE AS'!$H$4:$H$123,'Historique AE AS'!$D$4:$D$123,"AS"),"") | G15: Poids : 30%
B16: STATUT OBJECTIF | C16: =IF(NOT(ISNUMBER(C13)),"—",IF(C13>='KPI Agents'!$E$5,"Objectif Atteint ✅","Non Atteint ❌")) | E16: STATUT OBJECTIF | F16: =IF(NOT(ISNUMBER(F13)),"—",IF(F13>='KPI Agents'!$E$5,"Objectif Atteint ✅","Non Atteint ❌"))
B18: Moyennes issues de l'onglet « Historique AE AS », lui-même alimenté automatiquement par les grilles AE et AS. Fiche individuelle : onglet « Fiche Agent » · tableau complet : « KPI Agents » · détail par critère : « Analyse Critères ».

Sheet Fiche Agent
A2: FICHE AGENT — TABLEAU DE BORD INDIVIDUEL
A3: Saisissez un nom d'agent OU un log HERMES : tous les indicateurs et graphiques ci-dessous se recalculent automatiquement. Le log est prioritaire sur le nom s'il est renseigné.
A5: Nom de l'agent | D5: ou Log HERMES | F5: Année
A6: Abdellah Bettioua | F6: 2026
A8: AGENT ANALYSÉ → | C8: =IFERROR(IF($D$6<>"",INDEX('LOG Agent'!$A$2:$A$52,MATCH($D$6,'LOG Agent'!$B$2:$B$52,0)),$A$6),$A$6) | K8: =IF($C$8="","","Log : "&IFERROR(VLOOKUP($C$8,'LOG Agent'!$A:$B,2,FALSE),"?")) | N8: =IF($C$8="","","Rang : "&IFERROR(TEXT(INDEX('KPI Agents'!$T$12:$T$62,MATCH($C$8,'KPI Agents'!$A$12:$A$62,0)),"0")&" / "&TEXT(COUNTIF('KPI Agents'!$C$12:$C$62,">0"),"0"),"n/a")) | Q8: =IF($C$8="","⚠ Saisissez un nom ou un log.",IF(COUNTIFS('Historique AE AS'!$B$4:$B$123,$C$8,'Historique AE AS'!$L$4:$L$123,$F$6)=0,"⚠ Aucun audit sur l'année sélectionnée.",""))
A10: AUDITS | C10: EXPLOITABLES | E10: SCORE GLOBAL | G10: ÉCART VS CIBLE | I10: CONFORMITÉ | K10: FOND (70%) | M10: FORME (30%) | O10: COMPLÉTUDE | Q10: DMC MOYENNE | S10: NIVEAU
A11: =COUNTIFS('Historique AE AS'!$B$4:$B$123,$C$8,'Historique AE AS'!$L$4:$L$123,$F$6) | C11: =COUNTIFS('Historique AE AS'!$B$4:$B$123,$C$8,'Historique AE AS'!$L$4:$L$123,$F$6,'Historique AE AS'!$S$4:$S$123,"Oui") | E11: =$B$97 | G11: =IF(NOT(ISNUMBER($B$97)),"",$B$97-'KPI Agents'!$E$5) | I11: =$B$98 | K11: =$B$95 | M11: =$B$96 | O11: =$B$99 | Q11: =IFERROR(AVERAGEIFS('Historique AE AS'!$F$4:$F$123,'Historique AE AS'!$B$4:$B$123,$C$8,'Historique AE AS'!$L$4:$L$123,$F$6),"") | S11: =IF(NOT(ISNUMBER($B$97)),"—",IF($B$97>=0.9,"Excellent",IF($B$97>='KPI Agents'!$E$5,"Conforme",IF($B$97>='KPI Agents'!$E$5-0.1,"À accompagner","Critique"))))
A90: Les profils par critère portent sur toutes les écoutes de l'agent saisies dans les grilles (sans filtre d'année) ; les autres indicateurs suivent l'année sélectionnée.
A92: DONNÉES DES GRAPHIQUES — calculées automatiquement, ne rien modifier
A94: Indicateur | B94: Agent | C94: Centre
A95: Moyenne Fond | B95: =IFERROR(AVERAGEIFS('Historique AE AS'!$G$4:$G$123,'Historique AE AS'!$B$4:$B$123,$C$8,'Historique AE AS'!$L$4:$L$123,$F$6),"") | C95: =IFERROR(AVERAGEIFS('Historique AE AS'!$G$4:$G$123,'Historique AE AS'!$L$4:$L$123,$F$6),"")
A96: Moyenne Forme | B96: =IFERROR(AVERAGEIFS('Historique AE AS'!$H$4:$H$123,'Historique AE AS'!$B$4:$B$123,$C$8,'Historique AE AS'!$L$4:$L$123,$F$6),"") | C96: =IFERROR(AVERAGEIFS('Historique AE AS'!$H$4:$H$123,'Historique AE AS'!$L$4:$L$123,$F$6),"")
A97: Score global | B97: =IFERROR(AVERAGEIFS('Historique AE AS'!$I$4:$I$123,'Historique AE AS'!$B$4:$B$123,$C$8,'Historique AE AS'!$L$4:$L$123,$F$6),"") | C97: =IFERROR(AVERAGEIFS('Historique AE AS'!$I$4:$I$123,'Historique AE AS'!$L$4:$L$123,$F$6),"")
A98: Taux de conformité | B98: =IF(COUNTIFS('Historique AE AS'!$B$4:$B$123,$C$8,'Historique AE AS'!$L$4:$L$123,$F$6)=0,"",COUNTIFS('Historique AE AS'!$B$4:$B$123,$C$8,'Historique AE AS'!$L$4:$L$123,$F$6,'Historique AE AS'!$J$4:$J$123,"Objectif Atteint")/COUNTIFS('Historique AE AS'!$B$4:$B$123,$C$8,'Historique AE AS'!$L$4:$L$123,$F$6)) | C98: =IF(COUNTIFS('Historique AE AS'!$L$4:$L$123,$F$6)=0,"",COUNTIFS('Historique AE AS'!$L$4:$L$123,$F$6,'Historique AE AS'!$J$4:$J$123,"Objectif Atteint")/COUNTIFS('Historique AE AS'!$L$4:$L$123,$F$6))
A99: Complétude | B99: =IFERROR(AVERAGEIFS('Historique AE AS'!$R$4:$R$123,'Historique AE AS'!$B$4:$B$123,$C$8,'Historique AE AS'!$L$4:$L$123,$F$6),"") | C99: =IFERROR(AVERAGEIFS('Historique AE AS'!$R$4:$R$123,'Historique AE AS'!$L$4:$L$123,$F$6),"")
A101: Semaine | B101: Agent | C101: Centre | D101: Cible
A102: 1 | B102: =IFERROR(AVERAGEIFS('Historique AE AS'!$I$4:$I$123,'Historique AE AS'!$B$4:$B$123,$C$8,'Historique AE AS'!$L$4:$L$123,$F$6,'Historique AE AS'!$K$4:$K$123,$A102),"") | C102: =IFERROR(AVERAGEIFS('Historique AE AS'!$I$4:$I$123,'Historique AE AS'!$L$4:$L$123,$F$6,'Historique AE AS'!$K$4:$K$123,$A102),"") | D102: ='KPI Agents'!$E$5
A103: 2 | B103: =IFERROR(AVERAGEIFS('Historique AE AS'!$I$4:$I$123,'Historique AE AS'!$B$4:$B$123,$C$8,'Historique AE AS'!$L$4:$L$123,$F$6,'Historique AE AS'!$K$4:$K$123,$A103),"") | C103: =IFERROR(AVERAGEIFS('Historique AE AS'!$I$4:$I$123,'Historique AE AS'!$L$4:$L$123,$F$6,'Historique AE AS'!$K$4:$K$123,$A103),"") | D103: ='KPI Agents'!$E$5
A104: 3 | B104: =IFERROR(AVERAGEIFS('Historique AE AS'!$I$4:$I$123,'Historique AE AS'!$B$4:$B$123,$C$8,'Historique AE AS'!$L$4:$L$123,$F$6,'Historique AE AS'!$K$4:$K$123,$A104),"") | C104: =IFERROR(AVERAGEIFS('Historique AE AS'!$I$4:$I$123,'Historique AE AS'!$L$4:$L$123,$F$6,'Historique AE AS'!$K$4:$K$123,$A104),"") | D104: ='KPI Agents'!$E$5
A105: 4 | B105: =IFERROR(AVERAGEIFS('Historique AE AS'!$I$4:$I$123,'Historique AE AS'!$B$4:$B$123,$C$8,'Historique AE AS'!$L$4:$L$123,$F$6,'Historique AE AS'!$K$4:$K$123,$A105),"") | C105: =IFERROR(AVERAGEIFS('Historique AE AS'!$I$4:$I$123,'Historique AE AS'!$L$4:$L$123,$F$6,'Historique AE AS'!$K$4:$K$123,$A105),"") | D105: ='KPI Agents'!$E$5
A106: 5 | B106: =IFERROR(AVERAGEIFS('Historique AE AS'!$I$4:$I$123,'Historique AE AS'!$B$4:$B$123,$C$8,'Historique AE AS'!$L$4:$L$123,$F$6,'Historique AE AS'!$K$4:$K$123,$A106),"") | C106: =IFERROR(AVERAGEIFS('Historique AE AS'!$I$4:$I$123,'Historique AE AS'!$L$4:$L$123,$F$6,'Historique AE AS'!$K$4:$K$123,$A106),"") | D106: ='KPI Agents'!$E$5
A107: 6 | B107: =IFERROR(AVERAGEIFS('Historique AE AS'!$I$4:$I$123,'Historique AE AS'!$B$4:$B$123,$C$8,'Historique AE AS'!$L$4:$L$123,$F$6,'Historique AE AS'!$K$4:$K$123,$A107),"") | C107: =IFERROR(AVERAGEIFS('Historique AE AS'!$I$4:$I$123,'Historique AE AS'!$L$4:$L$123,$F$6,'Historique AE AS'!$K$4:$K$123,$A107),"") | D107: ='KPI Agents'!$E$5
A108: 7 | B108: =IFERROR(AVERAGEIFS('Historique AE AS'!$I$4:$I$123,'Historique AE AS'!$B$4:$B$123,$C$8,'Historique AE AS'!$L$4:$L$123,$F$6,'Historique AE AS'!$K$4:$K$123,$A108),"") | C108: =IFERROR(AVERAGEIFS('Historique AE AS'!$I$4:$I$123,'Historique AE AS'!$L$4:$L$123,$F$6,'Historique AE AS'!$K$4:$K$123,$A108),"") | D108: ='KPI Agents'!$E$5
A109: 8 | B109: =IFERROR(AVERAGEIFS('Historique AE AS'!$I$4:$I$123,'Historique AE AS'!$B$4:$B$123,$C$8,'Historique AE AS'!$L$4:$L$123,$F$6,'Historique AE AS'!$K$4:$K$123,$A109),"") | C109: =IFERROR(AVERAGEIFS('Historique AE AS'!$I$4:$I$123,'Historique AE AS'!$L$4:$L$123,$F$6,'Historique AE AS'!$K$4:$K$123,$A109),"") | D109: ='KPI Agents'!$E$5
A110: 9 | B110: =IFERROR(AVERAGEIFS('Historique AE AS'!$I$4:$I$123,'Historique AE AS'!$B$4:$B$123,$C$8,'Historique AE AS'!$L$4:$L$123,$F$6,'Historique AE AS'!$K$4:$K$123,$A110),"") | C110: =IFERROR(AVERAGEIFS('Historique AE AS'!$I$4:$I$123,'Historique AE AS'!$L$4:$L$123,$F$6,'Historique AE AS'!$K$4:$K$123,$A110),"") | D110: ='KPI Agents'!$E$5
A111: 10 | B111: =IFERROR(AVERAGEIFS('Historique AE AS'!$I$4:$I$123,'Historique AE AS'!$B$4:$B$123,$C$8,'Historique AE AS'!$L$4:$L$123,$F$6,'Historique AE AS'!$K$4:$K$123,$A111),"") | C111: =IFERROR(AVERAGEIFS('Historique AE AS'!$I$4:$I$123,'Historique AE AS'!$L$4:$L$123,$F$6,'Historique AE AS'!$K$4:$K$123,$A111),"") | D111: ='KPI Agents'!$E$5
A112: 11 | B112: =IFERROR(AVERAGEIFS('Historique AE AS'!$I$4:$I$123,'Historique AE AS'!$B$4:$B$123,$C$8,'Historique AE AS'!$L$4:$L$123,$F$6,'Historique AE AS'!$K$4:$K$123,$A112),"") | C112: =IFERROR(AVERAGEIFS('Historique AE AS'!$I$4:$I$123,'Historique AE AS'!$L$4:$L$123,$F$6,'Historique AE AS'!$K$4:$K$123,$A112),"") | D112: ='KPI Agents'!$E$5
A113: 12 | B113: =IFERROR(AVERAGEIFS('Historique AE AS'!$I$4:$I$123,'Historique AE AS'!$B$4:$B$123,$C$8,'Historique AE AS'!$L$4:$L$123,$F$6,'Historique AE AS'!$K$4:$K$123,$A113),"") | C113: =IFERROR(AVERAGEIFS('Historique AE AS'!$I$4:$I$123,'Historique AE AS'!$L$4:$L$123,$F$6,'Historique AE AS'!$K$4:$K$123,$A113),"") | D113: ='KPI Agents'!$E$5
... A154: 53 | B154: =IFERROR(AVERAGEIFS('Historique AE AS'!$I$4:$I$123,'Historique AE AS'!$B$4:$B$123,$C$8,'Historique AE AS'!$L$4:$L$123,$F$6,'Historique AE AS'!$K$4:$K$123,$A154),"") | C154: =IFERROR(AVERAGEIFS('Historique AE AS'!$I$4:$I$123,'Historique AE AS'!$L$4:$L$123,$F$6,'Historique AE AS'!$K$4:$K$123,$A154),"") | D154: ='KPI Agents'!$E$5
A156: Mois | B156: Agent | C156: Centre
A157: Janv. | B157: =IFERROR(AVERAGEIFS('Historique AE AS'!$I$4:$I$123,'Historique AE AS'!$B$4:$B$123,$C$8,'Historique AE AS'!$L$4:$L$123,$F$6,'Historique AE AS'!$T$4:$T$123,1),"") | C157: =IFERROR(AVERAGEIFS('Historique AE AS'!$I$4:$I$123,'Historique AE AS'!$L$4:$L$123,$F$6,'Historique AE AS'!$T$4:$T$123,1),"")
A158: Févr. | B158: =IFERROR(AVERAGEIFS('Historique AE AS'!$I$4:$I$123,'Historique AE AS'!$B$4:$B$123,$C$8,'Historique AE AS'!$L$4:$L$123,$F$6,'Historique AE AS'!$T$4:$T$123,2),"") | C158: =IFERROR(AVERAGEIFS('Historique AE AS'!$I$4:$I$123,'Historique AE AS'!$L$4:$L$123,$F$6,'Historique AE AS'!$T$4:$T$123,2),"")
A159: Mars | B159: =IFERROR(AVERAGEIFS('Historique AE AS'!$I$4:$I$123,'Historique AE AS'!$B$4:$B$123,$C$8,'Historique AE AS'!$L$4:$L$123,$F$6,'Historique AE AS'!$T$4:$T$123,3),"") | C159: =IFERROR(AVERAGEIFS('Historique AE AS'!$I$4:$I$123,'Historique AE AS'!$L$4:$L$123,$F$6,'Historique AE AS'!$T$4:$T$123,3),"")
A160: Avril | B160: =IFERROR(AVERAGEIFS('Historique AE AS'!$I$4:$I$123,'Historique AE AS'!$B$4:$B$123,$C$8,'Historique AE AS'!$L$4:$L$123,$F$6,'Historique AE AS'!$T$4:$T$123,4),"") | C160: =IFERROR(AVERAGEIFS('Historique AE AS'!$I$4:$I$123,'Historique AE AS'!$L$4:$L$123,$F$6,'Historique AE AS'!$T$4:$T$123,4),"")
A161: Mai | B161: =IFERROR(AVERAGEIFS('Historique AE AS'!$I$4:$I$123,'Historique AE AS'!$B$4:$B$123,$C$8,'Historique AE AS'!$L$4:$L$123,$F$6,'Historique AE AS'!$T$4:$T$123,5),"") | C161: =IFERROR(AVERAGEIFS('Historique AE AS'!$I$4:$I$123,'Historique AE AS'!$L$4:$L$123,$F$6,'Historique AE AS'!$T$4:$T$123,5),"")
A162: Juin | B162: =IFERROR(AVERAGEIFS('Historique AE AS'!$I$4:$I$123,'Historique AE AS'!$B$4:$B$123,$C$8,'Historique AE AS'!$L$4:$L$123,$F$6,'Historique AE AS'!$T$4:$T$123,6),"") | C162: =IFERROR(AVERAGEIFS('Historique AE AS'!$I$4:$I$123,'Historique AE AS'!$L$4:$L$123,$F$6,'Historique AE AS'!$T$4:$T$123,6),"")
A163: Juil. | B163: =IFERROR(AVERAGEIFS('Historique AE AS'!$I$4:$I$123,'Historique AE AS'!$B$4:$B$123,$C$8,'Historique AE AS'!$L$4:$L$123,$F$6,'Historique AE AS'!$T$4:$T$123,7),"") | C163: =IFERROR(AVERAGEIFS('Historique AE AS'!$I$4:$I$123,'Historique AE AS'!$L$4:$L$123,$F$6,'Historique AE AS'!$T$4:$T$123,7),"")
A164: Août | B164: =IFERROR(AVERAGEIFS('Historique AE AS'!$I$4:$I$123,'Historique AE AS'!$B$4:$B$123,$C$8,'Historique AE AS'!$L$4:$L$123,$F$6,'Historique AE AS'!$T$4:$T$123,8),"") | C164: =IFERROR(AVERAGEIFS('Historique AE AS'!$I$4:$I$123,'Historique AE AS'!$L$4:$L$123,$F$6,'Historique AE AS'!$T$4:$T$123,8),"")
A165: Sept. | B165: =IFERROR(AVERAGEIFS('Historique AE AS'!$I$4:$I$123,'Historique AE AS'!$B$4:$B$123,$C$8,'Historique AE AS'!$L$4:$L$123,$F$6,'Historique AE AS'!$T$4:$T$123,9),"") | C165: =IFERROR(AVERAGEIFS('Historique AE AS'!$I$4:$I$123,'Historique AE AS'!$L$4:$L$123,$F$6,'Historique AE AS'!$T$4:$T$123,9),"")
A166: Oct. | B166: =IFERROR(AVERAGEIFS('Historique AE AS'!$I$4:$I$123,'Historique AE AS'!$B$4:$B$123,$C$8,'Historique AE AS'!$L$4:$L$123,$F$6,'Historique AE AS'!$T$4:$T$123,10),"") | C166: =IFERROR(AVERAGEIFS('Historique AE AS'!$I$4:$I$123,'Historique AE AS'!$L$4:$L$123,$F$6,'Historique AE AS'!$T$4:$T$123,10),"")
...

Sheet Grille AE
A2: GUIDE METHODOLOGIQUE DE L'EVALUATEUR | G2: AE
F3: Nom de l'Agent : | G3: Abdellah Bettioua | H3: Aymen Gozar | I3: BATTAL SALMA | J3: CHAMCHATI Hajar | K3: BOURBAH AMINA
A4: 1. Choix de la Grille | B4: Selon le type d'appel à évaluer, rendez-vous sur l'onglet 'Grille AE' (Appel Entrant) ou 'Grille AS' (Appel Sortant). | F4: LOG Agent : | G4: =_xlfn.IFNA(VLOOKUP(G3,'LOG Agent'!$A:$B,2, FALSE), "") | H4: =_xlfn.IFNA(VLOOKUP(H3,'LOG Agent'!$A:$B,2, FALSE), "") | I4: =_xlfn.IFNA(VLOOKUP(I3,'LOG Agent'!$A:$B,2, FALSE), "") | J4: =_xlfn.IFNA(VLOOKUP(J3,'LOG Agent'!$A:$B,2, FALSE), "") | K4: =_xlfn.IFNA(VLOOKUP(K3,'LOG Agent'!$A:$B,2, FALSE), "") | L4: =_xlfn.IFNA(VLOOKUP(L3,'LOG Agent'!$A:$B,2, FALSE), "") | M4: =_xlfn.IFNA(VLOOKUP(M3,'LOG Agent'!$A:$B,2, FALSE), "") | N4: =_xlfn.IFNA(VLOOKUP(N3,'LOG Agent'!$A:$B,2, FALSE), "") | ... BN4: =_xlfn.IFNA(VLOOKUP(BN3,'LOG Agent'!$A:$B,2, FALSE), "")
A5: 2. Système de Notation | B5: Sélectionnez les notes (10, 5, 0, ou N/A) directement via les listes déroulantes de la colonne 'Note d'évaluation'. | F5: Date d'écoute : | G5: 46265 | H5: 46235 | I5: 46235 | J5: 46235 | K5: 46266
A6: 3. Règle de Neutralisation | B6: La valeur 'N/A' permet d'exclure un critère non applicable à l'appel sans impacter négativement la note globale de l'agent. | F6: Heure Début : | G6: 0.35416667 | H6: 0.33888889 | I6: 0.33888889 | J6: 0.33888889 | K6: 0.33333333
A7: 4. Pondération des Notes | B7: Les scores globaux sont pondérés à 70% sur le Fond (procédures, expertise) et 30% sur la Forme (comportement, courtoisie, voix). | F7: Heure Fin : | G7: 0.36111111 | H7: 0.34027778 | I7: 0.34027778 | J7: 0.34027778 | K7: 0.33472222
A8: 5. Plan d'Action | B8: En bas de chaque grille d'évaluation, renseignez les axes d'amélioration de l'agent pour assurer sa montée en compétences. | F8: Type d'écoute : | G8: Écoute à chaud | H8: Écoute à froid | I8: Écoute à froid | J8: Écoute à froid | K8: Écoute à froid
F9: Typologie de l'appel : | G9: Demande d'information | H9: Demande d'information | I9: Demande d'information | J9: Demande d'information | K9: Réclamation
F10: Objet de l'appel : | G10: BBM | H10: CC | I10: CC | J10: CC | K10: BBM
F11: Autre à saisir :
B12: AL BARID BANK | G12: Evaluation 1 | H12: Evaluation 2 | I12: Evaluation 3 | J12: Evaluation 4 | K12: Evaluation 5 | L12: Evaluation 6 | M12: Evaluation 7 | N12: Evaluation 8 | O12: Evaluation 9 | P12: Evaluation 10 | Q12: Evaluation 11 | R12: Evaluation 12 | S12: Evaluation 13 | T12: Evaluation 14 | U12: Evaluation 15 | V12: Evaluation 16 | W12: Evaluation 17 | X12: Evaluation 18 | Y12: Evaluation 19 | Z12: Evaluation 20 | AA12: Evaluation 21 | AB12: Evaluation 22 | AC12: Evaluation 23 | AD12: Evaluation 24 | AE12: Evaluation 25 | AF12: Evaluation 26 | AG12: Evaluation 27 | AH12: Evaluation 28 | AI12: Evaluation 29 | AJ12: Evaluation 30 | AK12: Evaluation 31 | AL12: Evaluation 32 | AM12: Evaluation 33 | AN12: Evaluation 34 | AO12: Evaluation 35 | AP12: Evaluation 36 | AQ12: Evaluation 37 | AR12: Evaluation 38 | AS12: Evaluation 39 | AT12: Evaluation 40 | AU12: Evaluation 41 | AV12: Evaluation 42 | AW12: Evaluation 43 | AX12: Evaluation 44 | AY12: Evaluation 45 | AZ12: Evaluation 46 | BA12: Evaluation 47 | BB12: Evaluation 48 | BC12: Evaluation 49 | BD12: Evaluation 50 | BE12: Evaluation 51 | BF12: Evaluation 52 | BG12: Evaluation 53 | BH12: Evaluation 54 | BI12: Evaluation 55 | BJ12: Evaluation 56 | BK12: Evaluation 57 | BL12: Evaluation 58 | BM12: Evaluation 59 | BN12: Evaluation 60
B13: GRILLE D'ÉVALUATION DES APPELS ENTRANTS (AE)
B14: A. ÉVALUATION DU FOND (Pondération : 70% dans le Score Global)
B15: Ref | C15: Catégorie | D15: Critère d'évaluation | E15: Note | F15: Guide de notation / Barème
B16: F01 | C16: Fond | D16: L'agent cherche à mieux connaître le client (pose des questions sur son identité, sa situation et son besoin) | E16: =IFERROR(AVERAGE(G16:BN16),"") | F16: 10 : Recherche complète (identité, situation, besoin) 5 : Recherche incomplète 0 : Pas de recherche | G16: 10 | H16: 5 | I16: 10
B17: F02 | D17: L'agent ne déborde pas sur des sujets sans rapport avec la demande du client | E17: =IFERROR(AVERAGE(G17:BN17),"") | F17: 10 : Reste focalisé sur la demande 0 : Hors sujet ou bavardage inutile | G17: 5 | H17: 5 | J17: 10 | K17: 5
B18: F03 | D18: L'agent demande l'autorisation de collecter les informations personnelles de la relation (Sécurité/RGPD) | E18: =IFERROR(AVERAGE(G18:BN18),"") | F18: 10 : Demande systématique d'autorisation 0 : Pas de demande d'autorisation | G18: 10 | H18: 5
B19: F04 | D19: L'agent fournit au client des réponses claires et complètes à sa demande (Expertise) | E19: =IFERROR(AVERAGE(G19:BN19),"") | F19: 10 : Réponses complètes et correctes 0 : Réponse incomplète ou erronée | G19: 10 | H19: 0
B20: F05 | D20: La mise en attente du client est justifiée / n'est pas justifiée | E20: =IFERROR(AVERAGE(G20:BN20),"") | F20: 10 : Attente nécessaire et justifiée 0 : Attente abusive ou injustifiée | G20: 5 | H20: 5
B21: F06 | D21: L'agent propose au client des produits adaptés à son besoin (Rebond commercial) | E21: =IFERROR(AVERAGE(G21:BN21),"") | F21: 10 : Rebond commercial pertinent 0 : Pas de proposition ou rebond inadapté | G21: 10 | H21: 10
B22: F07 | D22: Orienter le client vers les solutions digitales (vidéos, tutoriels, etc.) | E22: =IFERROR(AVERAGE(G22:BN22),"") | F22: 10 : Proposition active des canaux digitaux 5 : Proposition timide ou partielle 0 : Pas d'orientation digitale | G22: 10 | H22: 10
B23: F08 | D23: L'agent respecte les procédures / prossessus d'Al Barid Bank (Conformité) | E23: =IFERROR(AVERAGE(G23:BN23),"") | F23: 10 : Procédures respectées de bout en bout 0 : Non-respect d'une procédure | G23: 10 | H23: 10
B24: F09 | D24: L'agent maîtrise les produits et services de la banque (Savoir-faire) | E24: =IFERROR(AVERAGE(G24:BN24),"") | F24: 10 : Maîtrise parfaite 5 : Hésitations ou besoin de recherche long 0 : Méconnaissance flagrante | G24: 10 | H24: 10
B25: F10 | D25: L'agent respecte le temps de communication (DMC) selon la demande du client | E25: =IFERROR(AVERAGE(G25:BN25),"") | F25: 10 : DMC optimale et maîtrisée 5 : Léger dépassement 0 : Traitement anormalement long | G25: 10 | H25: 5
B26: B. ÉVALUATION DE LA FORME (Pondération : 30% dans le Score Global)
B27: R01 | C27: Forme | D27: L'agent accueille le client avec la formule d’usage : « Al Barid Bank, Bonjour » | E27: =IFERROR(AVERAGE(G27:BN27),"") | F27: 10 : Accueil conforme 0 : Formule déformée ou manquante | G27: 10 | H27: 5 | I27: 10
B28: R02 | D28: L'agent se présente (Annonce son nom/prénom) X à votre service | E28: =IFERROR(AVERAGE(G28:BN28),"") | F28: 10 : Présentation conforme 0 : Présentation incomplète ou manquante | G28: 10 | H28: 0
B29: R03 | D29: L'agent écoute le client attentivement et sans l'interrompre | E29: =IFERROR(AVERAGE(G29:BN29),"") | F29: 10 : Écoute active et respectueuse 5 : Interruptions mineures 0 : Interruptions répétées | G29: 10 | H29: 10 | K29: 10
B30: R04 | D30: L'agent reformule la demande du client | E30: =IFERROR(AVERAGE(G30:BN30),"") | F30: 10 : Reformulation claire et précise 5 : Reformulation partielle ou peu claire 0 : Pas de reformulation | G30: 5
B31: R05 | D31: Pendant qu’il effectue des recherches sur écran, l'agent explique au client ce qu’il fait | E31: =IFERROR(AVERAGE(G31:BN31),"") | F31: 10 : Meuble l'attente en expliquant ses actions 0 : Silence radio durant les recherches | G31: 5
B32: R06 | D32: L'agent annonce au client qu'il va le mettre en attente | E32: =IFERROR(AVERAGE(G32:BN32),"") | F32: 10 : Annonce claire et polie 0 : Mise en attente sans prévenir | G32: 5
B33: R07 | D33: L'agent remercie le client de la mise en attente | E33: =IFERROR(AVERAGE(G33:BN33),"") | F33: 10 : Remerciements systématiques 0 : Pas de remerciements au retour d'attente | G33: 10
B34: R08 | D34: L'agent personnalise l’appel, appelle le client par son nom au moins deux fois | E34: =IFERROR(AVERAGE(G34:BN34),"") | F34: 10 : Nom utilisé au moins 2 fois 5 : Nom utilisé une seule fois 0 : Appel impersonnel | G34: 10
B35: R09 | D35: L'agent a une bonne élocution avec un discours positif et convaincant | E35: =IFERROR(AVERAGE(G35:BN35),"") | F35: 10 : Élocution fluide, vocabulaire pro et positif 5 : Élocution moyenne ou manque d'entrain 0 : Vocabulaire inadapté | G35: 10
B36: R10 | D36: L'agent adapte son discours au client | E36: =IFERROR(AVERAGE(G36:BN36),"") | F36: 10 : Parfaite synchronisation et adaptation au client 0 : Pas d'adaptation | G36: 10
B37: R11 | D37: L'agent s'exprime d'une manière respectueuse | E37: =IFERROR(AVERAGE(G37:BN37),"") | F37: 10 : Respect absolu du client 0 : Manque de respect | G37: 10
B38: R12 | D38: L'agent fait preuve de courtoisie et d'une attitude chaleureuse (Sourire audible, formules de politesse) | E38: =IFERROR(AVERAGE(G38:BN38),"") | F38: 10 : Sourire s'entendant au téléphone, bienveillance relationnelle et politesse irréprochable 5 : Ton poli mais froid 0 : Ton cassant ou manque de politesse | G38: 10
B39: R13 | D39: L'agent maîtrise le ton de sa voix, son débit et son rythme | E39: =IFERROR(AVERAGE(G39:BN39),"") | F39: 10 : Voix dynamique et posée, débit adapté 5 : Voix monocorde ou débit trop rapide/lent 0 : Ton agressif ou débit inintelligible | G39: 10
B40: R14 | D40: L’agent s'assure que le client dispose de toutes les informations avant de prendre congé | E40: =IFERROR(AVERAGE(G40:BN40),"") | F40: 10 : Validation de fin systématique 0 : Pas de validation | G40: 10 | J40: 10
B41: R15 | D41: L'agent utilise les formules d’usage pour les remerciements et les au-revoir | E41: =IFERROR(AVERAGE(G41:BN41),"") | F41: 10 : Formule de congé complète et polie 0 : Congé bâclé ou impoli | G41: 0
...

Sheet Objet&TYP
A1: AS | F1: AE
A2: Campagnes | F2: Demande d'information
A3: Demande de service | F3: Demande de service
A4: Réclamation | F4: Réclamation
A5: Tombola | F5: Suggestion
A6: Se faire rappeler
A8: Entrée en relation | F8: Monétique
A9: Monétique | F9: BBM
A10: BBM | F10: CC
A11: CC | F11: CEN
A12: CEN | F12: Qualité de service
A13: Qualité de service | F13: Crédits
A14: Crédits | F14: Transferts
A15: Transferts | F15: Bancassurance
A16: Bancassurance | F16: Autres
A17: Saltcl
A18: Autres

Sheet Grille AS
A2: GUIDE METHODOLOGIQUE DE L'EVALUATEUR | G2: AS
F3: Nom de l'Agent : | G3: Abdellah Bettioua
A4: 1. Choix de la Grille | B4: Selon le type d'appel à évaluer, rendez-vous sur l'onglet 'Grille AE' (Appel Entrant) ou 'Grille AS' (Appel Sortant). | F4: LOG Agent : | G4: =_xlfn.IFNA(VLOOKUP(G3,'LOG Agent'!$A:$B,2, FALSE), "") | H4: =_xlfn.IFNA(VLOOKUP(H3,'LOG Agent'!$A:$B,2, FALSE), "") | I4: =_xlfn.IFNA(VLOOKUP(I3,'LOG Agent'!$A:$B,2, FALSE), "") | J4: =_xlfn.IFNA(VLOOKUP(J3,'LOG Agent'!$A:$B,2, FALSE), "") | K4: =_xlfn.IFNA(VLOOKUP(K3,'LOG Agent'!$A:$B,2, FALSE), "") | L4: =_xlfn.IFNA(VLOOKUP(L3,'LOG Agent'!$A:$B,2, FALSE), "") | M4: =_xlfn.IFNA(VLOOKUP(M3,'LOG Agent'!$A:$B,2, FALSE), "") | N4: =_xlfn.IFNA(VLOOKUP(N3,'LOG Agent'!$A:$B,2, FALSE), "") | ... BN4: =_xlfn.IFNA(VLOOKUP(BN3,'LOG Agent'!$A:$B,2, FALSE), "")
A5: 2. Système de Notation | B5: Sélectionnez les notes (10, 5, 0, ou N/A) directement via les listes déroulantes de la colonne 'Note d'évaluation'. | F5: Date d'écoute : | G5: 46262
A6: 3. Règle de Neutralisation | B6: La valeur 'N/A' permet d'exclure un critère non applicable à l'appel sans impacter négativement la note globale de l'agent. | F6: Heure Début : | G6: 0.38194444
A7: 4. Pondération des Notes | B7: Les scores globaux sont pondérés à 70% sur le Fond (procédures, expertise) et 30% sur la Forme (comportement, courtoisie, voix). | F7: Heure Fin : | G7: 0.38541667
A8: 5. Plan d'Action | B8: En bas de chaque grille d'évaluation, renseignez les axes d'amélioration de l'agent pour assurer sa montée en compétences. | F8: Type d'écoute : | G8: Écoute à froid
F9: Typologie de l'appel : | G9: Réclamation
F10: Objet de l'appel : | G10: CC
F11: Autre à saisir :
B12: AL BARID BANK | G12: Evaluation 1 | H12: Evaluation 2 | I12: Evaluation 3 | J12: Evaluation 4 | K12: Evaluation 5 | L12: Evaluation 6 | M12: Evaluation 7 | N12: Evaluation 8 | O12: Evaluation 9 | P12: Evaluation 10 | Q12: Evaluation 11 | R12: Evaluation 12 | S12: Evaluation 13 | T12: Evaluation 14 | U12: Evaluation 15 | V12: Evaluation 16 | W12: Evaluation 17 | X12: Evaluation 18 | Y12: Evaluation 19 | Z12: Evaluation 20 | AA12: Evaluation 21 | AB12: Evaluation 22 | AC12: Evaluation 23 | AD12: Evaluation 24 | AE12: Evaluation 25 | AF12: Evaluation 26 | AG12: Evaluation 27 | AH12: Evaluation 28 | AI12: Evaluation 29 | AJ12: Evaluation 30 | AK12: Evaluation 31 | AL12: Evaluation 32 | AM12: Evaluation 33 | AN12: Evaluation 34 | AO12: Evaluation 35 | AP12: Evaluation 36 | AQ12: Evaluation 37 | AR12: Evaluation 38 | AS12: Evaluation 39 | AT12: Evaluation 40 | AU12: Evaluation 41 | AV12: Evaluation 42 | AW12: Evaluation 43 | AX12: Evaluation 44 | AY12: Evaluation 45 | AZ12: Evaluation 46 | BA12: Evaluation 47 | BB12: Evaluation 48 | BC12: Evaluation 49 | BD12: Evaluation 50 | BE12: Evaluation 51 | BF12: Evaluation 52 | BG12: Evaluation 53 | BH12: Evaluation 54 | BI12: Evaluation 55 | BJ12: Evaluation 56 | BK12: Evaluation 57 | BL12: Evaluation 58 | BM12: Evaluation 59 | BN12: Evaluation 60
B13: GRILLE D'ÉVALUATION DES APPELS SORTANTS (AS)
B14: A. ÉVALUATION DU FOND (Pondération : 70% dans le Score Global)
B15: Ref | C15: Catégorie | D15: Critère d'évaluation | E15: Note | F15: Guide de notation / Barème
B16: F01 | C16: Fond | D16: L'agent respecte le script (à renseigner en cas de campagnes) | E16: =IFERROR(AVERAGE(G16:BN16),"") | F16: 10 : Respect strict du script 0 : Non-respect du script | G16: 10
B17: F02 | D17: L'agent informe le client que l'appel est enregistré (Réglementaire) | E17: =IFERROR(AVERAGE(G17:BN17),"") | F17: 10 : Annonce faite au départ 0 : Annonce omise | G17: 10
B18: F03 | D18: L'agent respecte la procédure / processus (à renseigner en cas de demande de service) | E18: =IFERROR(AVERAGE(G18:BN18),"") | F18: 10 : Procédure parfaitement respectée 0 : Procédure non respectée | G18: 10
B19: F04 | D19: L'agent respecte la thématique de l'appel | E19: =IFERROR(AVERAGE(G19:BN19),"") | F19: 10 : Reste centré sur le sujet 0 : Déviation injustifiée | G19: 10
B20: F05 | D20: L'agent maîtrise les produits et services relatifs à la prestation objet de l'appel | E20: =IFERROR(AVERAGE(G20:BN20),"") | F20: 10 : Maîtrise parfaite 5 : Hésitations ou imprécisions 0 : Erreurs ou méconnaissance | G20: 10
B21: F06 | D21: En cas de demande hors contexte, l'agent propose la solution adéquate (Traitement / redirection CRC) | E21: =IFERROR(AVERAGE(G21:BN21),"") | F21: 10 : Orientation ou traitement conforme 0 : Refus de traitement ou mauvaise orientation | G21: 10
B22: F07 | D22: L'agent respecte le temps de communication (DMC) selon la demande du client | E22: =IFERROR(AVERAGE(G22:BN22),"") | F22: 10 : DMC optimale et maîtrisée 5 : Léger débordement 0 : Traitement anormalement long | G22: 10
B23: B. ÉVALUATION DE LA FORME (Pondération : 30% dans le Score Global)
B24: R01 | C24: Forme | D24: Salutations : Bonjour, je suis bien avec M/mme [Nom du client], je suis [Nom de l'agent] d’Al Barid Bank. | E24: =IFERROR(AVERAGE(G24:BN24),"") | F24: 10 : Salutations et présentation conformes 0 : Présentation manquante ou erronée | G24: 10
B25: R02 | D25: L'agent demande au client son accord / disponibilité avant de démarrer l'entretien | E25: =IFERROR(AVERAGE(G25:BN25),"") | F25: 10 : Disponibilité validée avec courtoisie 0 : Entretien démarré sans accord | G25: 10
B26: R03 | D26: L'agent personnalise l'appel, appelle le client par son nom au moins deux fois | E26: =IFERROR(AVERAGE(G26:BN26),"") | F26: 10 : Nom cité au moins 2 fois 5 : Nom cité une seule fois 0 : Pas de personnalisation | G26: 10
B27: R04 | D27: L'agent a une bonne élocution et s'exprime d'une manière respectueuse | E27: =IFERROR(AVERAGE(G27:BN27),"") | F27: 10 : Élocution fluide, vocabulaire respectueux 0 : Langage familier ou manque de respect | G27: 10
B28: R05 | D28: L'agent adapte son discours au client (Empathie / Ton) | E28: =IFERROR(AVERAGE(G28:BN28),"") | F28: 10 : Posture et langage adaptés au profil du client 0 : Discours rigide ou inadapté | G28: 10
B29: R06 | D29: L'agent fait preuve de courtoisie et d'une attitude chaleureuse (Sourire audible, formules de politesse) | E29: =IFERROR(AVERAGE(G29:BN29),"") | F29: 10 : Sourire s'entendant au téléphone, bienveillance relationnelle et politesse irréprochable 5 : Ton poli mais froid 0 : Ton cassant ou manque de politesse | G29: 10
B30: R07 | D30: L'agent maîtrise le ton de sa voix, son débit et son rythme | E30: =IFERROR(AVERAGE(G30:BN30),"") | F30: 10 : Voix dynamique et posée, débit adapté 5 : Débit trop rapide/lent ou voix monocorde 0 : Ton agressif ou inaudible | G30: 10
B31: R08 | D31: L'agent utilise les formules d’usage pour les remerciements et les au-revoir | E31: =IFERROR(AVERAGE(G31:BN31),"") | F31: 10 : Remerciements et prise de congé professionnels 0 : Congé bâclé ou impoli | G31: 10
B32: Commentaires / Observations
B33: C. SYNTHÈSE DES SCORES DE L'APPEL SORTANT (AS)
D34: Moyenne FOND (sur 100%) : | E34: =IFERROR(AVERAGEIFS(E16:E22,E16:E22,"<>N/A")/10,"") | G34: =IFERROR(AVERAGEIFS(G16:G22,G16:G22,"<>N/A")/10,"") | H34: =IFERROR(AVERAGEIFS(H16:H22,H16:H22,"<>N/A")/10,"") | I34: =IFERROR(AVERAGEIFS(I16:I22,I16:I22,"<>N/A")/10,"") | J34: =IFERROR(AVERAGEIFS(J16:J22,J16:J22,"<>N/A")/10,"") | K34: =IFERROR(AVERAGEIFS(K16:K22,K16:K22,"<>N/A")/10,"") | L34: =IFERROR(AVERAGEIFS(L16:L22,L16:L22,"<>N/A")/10,"") | M34: =IFERROR(AVERAGEIFS(M16:M22,M16:M22,"<>N/A")/10,"") | N34: =IFERROR(AVERAGEIFS(N16:N22,N16:N22,"<>N/A")/10,"") | ... BN34: =IFERROR(AVERAGEIFS(BN16:BN22,BN16:BN22,"<>N/A")/10,"")
D35: Moyenne FORME (sur 100%) : | E35: =IFERROR(AVERAGEIFS(E24:E31,E24:E31,"<>N/A")/10,"") | G35: =IFERROR(AVERAGEIFS(G24:G31,G24:G31,"<>N/A")/10,"") | H35: =IFERROR(AVERAGEIFS(H24:H31,H24:H31,"<>N/A")/10,"") | I35: =IFERROR(AVERAGEIFS(I24:I31,I24:I31,"<>N/A")/10,"") | J35: =IFERROR(AVERAGEIFS(J24:J31,J24:J31,"<>N/A")/10,"") | K35: =IFERROR(AVERAGEIFS(K24:K31,K24:K31,"<>N/A")/10,"") | L35: =IFERROR(AVERAGEIFS(L24:L31,L24:L31,"<>N/A")/10,"") | M35: =IFERROR(AVERAGEIFS(M24:M31,M24:M31,"<>N/A")/10,"") | N35: =IFERROR(AVERAGEIFS(N24:N31,N24:N31,"<>N/A")/10,"") | ... BN35: =IFERROR(AVERAGEIFS(BN24:BN31,BN24:BN31,"<>N/A")/10,"")
D36: SCORE GLOBAL PONDÉRÉ (70% Fond / 30% Forme) : | E36: =IF(OR(NOT(ISNUMBER(E34)),NOT(ISNUMBER(E35))),"",E34*0.7+E35*0.3) | G36: =IF(OR(NOT(ISNUMBER(G34)),NOT(ISNUMBER(G35))),"",G34*0.7+G35*0.3) | H36: =IF(OR(NOT(ISNUMBER(H34)),NOT(ISNUMBER(H35))),"",H34*0.7+H35*0.3) | I36: =IF(OR(NOT(ISNUMBER(I34)),NOT(ISNUMBER(I35))),"",I34*0.7+I35*0.3) | J36: =IF(OR(NOT(ISNUMBER(J34)),NOT(ISNUMBER(J35))),"",J34*0.7+J35*0.3) | K36: =IF(OR(NOT(ISNUMBER(K34)),NOT(ISNUMBER(K35))),"",K34*0.7+K35*0.3) | L36: =IF(OR(NOT(ISNUMBER(L34)),NOT(ISNUMBER(L35))),"",L34*0.7+L35*0.3) | M36: =IF(OR(NOT(ISNUMBER(M34)),NOT(ISNUMBER(M35))),"",M34*0.7+M35*0.3) | N36: =IF(OR(NOT(ISNUMBER(N34)),NOT(ISNUMBER(N35))),"",N34*0.7+N35*0.3) | ... BN36: =IF(OR(NOT(ISNUMBER(BN34)),NOT(ISNUMBER(BN35))),"",BN34*0.7+BN35*0.3)
D37: STATUT OBJECTIF : | E37: =IF(ISNUMBER(E36),IF(E36>='KPI Agents'!$E$5,"Objectif Atteint ✅","Non Atteint ❌"),"") | G37: =IF(ISNUMBER(G36),IF(G36>='KPI Agents'!$E$5,"Objectif Atteint ✅","Non Atteint ❌"),"") | H37: =IF(ISNUMBER(H36),IF(H36>='KPI Agents'!$E$5,"Objectif Atteint ✅","Non Atteint ❌"),"") | I37: =IF(ISNUMBER(I36),IF(I36>='KPI Agents'!$E$5,"Objectif Atteint ✅","Non Atteint ❌"),"") | J37: =IF(ISNUMBER(J36),IF(J36>='KPI Agents'!$E$5,"Objectif Atteint ✅","Non Atteint ❌"),"") | K37: =IF(ISNUMBER(K36),IF(K36>='KPI Agents'!$E$5,"Objectif Atteint ✅","Non Atteint ❌"),"") | L37: =IF(ISNUMBER(L36),IF(L36>='KPI Agents'!$E$5,"Objectif Atteint ✅","Non Atteint ❌"),"") | M37: =IF(ISNUMBER(M36),IF(M36>='KPI Agents'!$E$5,"Objectif Atteint ✅","Non Atteint ❌"),"") | N37: =IF(ISNUMBER(N36),IF(N36>='KPI Agents'!$E$5,"Objectif Atteint ✅","Non Atteint ❌"),"") | ... BN37: =IF(ISNUMBER(BN36),IF(BN36>='KPI Agents'!$E$5,"Objectif Atteint ✅","Non Atteint ❌"),"")
B38: PLAN D'ACTION ET AXES DE PROGRÈS DE L'AGENT
B39: Saisir ici les points forts, les axes d'amélioration identifiés et les actions d'accompagnement prévues (formations, écoutes côte à côte, coaching spécifique, etc.).

Sheet LOG Agent
A1: Nom & Prénom | B1: Log HERMES
A2: Abdelaadim Codry | B2: 3085
A3: Abdellah Bettioua | B3: 3025
A4: ANAS DAHIBI | B4: 3515
A5: ANOUD OMAR | B5: 3485
A6: AYACHY YOUSSEF | B6: 3498
A7: Aymen Gozar | B7: 3034
A8: BATTAL SALMA | B8: 3071
A9: BEGGALI NOUR EL HOUDA | B9: 3448
A10: BOUIMZGANE YASSER | B10: 3494
A11: BOURBAH AMINA | B11: 3487
A12: CHAMCHATI Hajar | B12: 3036
A13: CHERRABI YOUSSEF | B13: 3451
... A52: ZOUIANE OUSSAMA | B52: 3484

Sheet Historique AE AS
A1: HISTORIQUE DES ÉVALUATIONS AE / AS
A2: Feuille 100 % calculée — aucune saisie ici. Chaque ligne reflète une colonne d'évaluation des onglets « Grille AE » et « Grille AS » ; elle se remplit dès qu'un nom d'agent est choisi dans la grille correspondante.
A3: Date d'écoute | B3: Nom de l'Agent | C3: LOG Agent | D3: Type d'appel | E3: Objet de l'appel | F3: DMC (min) | G3: Moyenne Fond | H3: Moyenne Forme | I3: Score Global | J3: Statut | K3: Semaine | L3: Année | M3: Source | N3: Colonne Audit | O3: Typologie de l'appel | P3: Type d'écoute | Q3: Critères renseignés | R3: Complétude | S3: Audit exploitable | T3: Mois
A4: =IF(OR(INDEX('Grille AE'!$G$3:$BN$3,1,1)="",INDEX('Grille AE'!$G$5:$BN$5,1,1)=""),"",INDEX('Grille AE'!$G$5:$BN$5,1,1)) | B4: =IFERROR(IF(INDEX('Grille AE'!$G$3:$BN$3,1,1)="","",INDEX('Grille AE'!$G$3:$BN$3,1,1)),"") | C4: =IF($B4="","",IFERROR(INDEX('Grille AE'!$G$4:$BN$4,1,1),"")) | D4: =IF($B4="","","AE") | E4: =IF($B4="","",IF(INDEX('Grille AE'!$G$10:$BN$10,1,1)="","",INDEX('Grille AE'!$G$10:$BN$10,1,1))) | F4: =IF($B4="","",IF(OR(INDEX('Grille AE'!$G$6:$BN$6,1,1)="",INDEX('Grille AE'!$G$7:$BN$7,1,1)=""),"",ROUND(MOD(INDEX('Grille AE'!$G$7:$BN$7,1,1)-INDEX('Grille AE'!$G$6:$BN$6,1,1),1)*1440,0))) | G4: =IF($B4="","",IFERROR(INDEX('Grille AE'!$G$44:$BN$44,1,1),"")) | H4: =IF($B4="","",IFERROR(INDEX('Grille AE'!$G$45:$BN$45,1,1),"")) | I4: =IF($B4="","",IFERROR(INDEX('Grille AE'!$G$46:$BN$46,1,1),"")) | J4: =IF(NOT(ISNUMBER($I4)),"",IF($I4>='KPI Agents'!$E$5,"Objectif Atteint","Non Atteint")) | K4: =IF(NOT(ISNUMBER($A4)),"",_xlfn.ISOWEEKNUM($A4)) | L4: =IF(NOT(ISNUMBER($A4)),"",YEAR($A4)) | M4: =IF($B4="","","Grille AE") | N4: =IF($B4="","",SUBSTITUTE(ADDRESS(1,6+1,4),"1","")) | O4: =IF($B4="","",IF(INDEX('Grille AE'!$G$9:$BN$9,1,1)="","",INDEX('Grille AE'!$G$9:$BN$9,1,1))) | P4: =IF($B4="","",IF(INDEX('Grille AE'!$G$8:$BN$8,1,1)="","",INDEX('Grille AE'!$G$8:$BN$8,1,1))) | Q4: =IF($B4="","",COUNTA(INDEX('Grille AE'!$G$16:$BN$25,1,1):INDEX('Grille AE'!$G$16:$BN$25,10,1))+COUNTA(INDEX('Grille AE'!$G$27:$BN$41,1,1):INDEX('Grille AE'!$G$27:$BN$41,15,1))) | R4: =IF(NOT(ISNUMBER($Q4)),"",$Q4/25) | S4: =IF(NOT(ISNUMBER($R4)),"",IF($R4>='KPI Agents'!$F$5,"Oui","Non")) | T4: =IF(NOT(ISNUMBER($A4)),"",MONTH($A4))
A5: =IF(OR(INDEX('Grille AE'!$G$3:$BN$3,1,2)="",INDEX('Grille AE'!$G$5:$BN$5,1,2)=""),"",INDEX('Grille AE'!$G$5:$BN$5,1,2)) | B5: =IFERROR(IF(INDEX('Grille AE'!$G$3:$BN$3,1,2)="","",INDEX('Grille AE'!$G$3:$BN$3,1,2)),"") | C5: =IF($B5="","",IFERROR(INDEX('Grille AE'!$G$4:$BN$4,1,2),"")) | D5: =IF($B5="","","AE") | E5: =IF($B5="","",IF(INDEX('Grille AE'!$G$10:$BN$10,1,2)="","",INDEX('Grille AE'!$G$10:$BN$10,1,2))) | F5: =IF($B5="","",IF(OR(INDEX('Grille AE'!$G$6:$BN$6,1,2)="",INDEX('Grille AE'!$G$7:$BN$7,1,2)=""),"",ROUND(MOD(INDEX('Grille AE'!$G$7:$BN$7,1,2)-INDEX('Grille AE'!$G$6:$BN$6,1,2),1)*1440,0))) | G5: =IF($B5="","",IFERROR(INDEX('Grille AE'!$G$44:$BN$44,1,2),"")) | H5: =IF($B5="","",IFERROR(INDEX('Grille AE'!$G$45:$BN$45,1,2),"")) | I5: =IF($B5="","",IFERROR(INDEX('Grille AE'!$G$46:$BN$46,1,2),"")) | J5: =IF(NOT(ISNUMBER($I5)),"",IF($I5>='KPI Agents'!$E$5,"Objectif Atteint","Non Atteint")) | K5: =IF(NOT(ISNUMBER($A5)),"",_xlfn.ISOWEEKNUM($A5)) | L5: =IF(NOT(ISNUMBER($A5)),"",YEAR($A5)) | M5: =IF($B5="","","Grille AE") | N5: =IF($B5="","",SUBSTITUTE(ADDRESS(1,6+2,4),"1","")) | O5: =IF($B5="","",IF(INDEX('Grille AE'!$G$9:$BN$9,1,2)="","",INDEX('Grille AE'!$G$9:$BN$9,1,2))) | P5: =IF($B5="","",IF(INDEX('Grille AE'!$G$8:$BN$8,1,2)="","",INDEX('Grille AE'!$G$8:$BN$8,1,2))) | Q5: =IF($B5="","",COUNTA(INDEX('Grille AE'!$G$16:$BN$25,1,2):INDEX('Grille AE'!$G$16:$BN$25,10,2))+COUNTA(INDEX('Grille AE'!$G$27:$BN$41,1,2):INDEX('Grille AE'!$G$27:$BN$41,15,2))) | R5: =IF(NOT(ISNUMBER($Q5)),"",$Q5/25) | S5: =IF(NOT(ISNUMBER($R5)),"",IF($R5>='KPI Agents'!$F$5,"Oui","Non")) | T5: =IF(NOT(ISNUMBER($A5)),"",MONTH($A5))
A6: =IF(OR(INDEX('Grille AE'!$G$3:$BN$3,1,3)="",INDEX('Grille AE'!$G$5:$BN$5,1,3)=""),"",INDEX('Grille AE'!$G$5:$BN$5,1,3)) | B6: =IFERROR(IF(INDEX('Grille AE'!$G$3:$BN$3,1,3)="","",INDEX('Grille AE'!$G$3:$BN$3,1,3)),"") | C6: =IF($B6="","",IFERROR(INDEX('Grille AE'!$G$4:$BN$4,1,3),"")) | D6: =IF($B6="","","AE") | E6: =IF($B6="","",IF(INDEX('Grille AE'!$G$10:$BN$10,1,3)="","",INDEX('Grille AE'!$G$10:$BN$10,1,3))) | F6: =IF($B6="","",IF(OR(INDEX('Grille AE'!$G$6:$BN$6,1,3)="",INDEX('Grille AE'!$G$7:$BN$7,1,3)=""),"",ROUND(MOD(INDEX('Grille AE'!$G$7:$BN$7,1,3)-INDEX('Grille AE'!$G$6:$BN$6,1,3),1)*1440,0))) | G6: =IF($B6="","",IFERROR(INDEX('Grille AE'!$G$44:$BN$44,1,3),"")) | H6: =IF($B6="","",IFERROR(INDEX('Grille AE'!$G$45:$BN$45,1,3),"")) | I6: =IF($B6="","",IFERROR(INDEX('Grille AE'!$G$46:$BN$46,1,3),"")) | J6: =IF(NOT(ISNUMBER($I6)),"",IF($I6>='KPI Agents'!$E$5,"Objectif Atteint","Non Atteint")) | K6: =IF(NOT(ISNUMBER($A6)),"",_xlfn.ISOWEEKNUM($A6)) | L6: =IF(NOT(ISNUMBER($A6)),"",YEAR($A6)) | M6: =IF($B6="","","Grille AE") | N6: =IF($B6="","",SUBSTITUTE(ADDRESS(1,6+3,4),"1","")) | O6: =IF($B6="","",IF(INDEX('Grille AE'!$G$9:$BN$9,1,3)="","",INDEX('Grille AE'!$G$9:$BN$9,1,3))) | P6: =IF($B6="","",IF(INDEX('Grille AE'!$G$8:$BN$8,1,3)="","",INDEX('Grille AE'!$G$8:$BN$8,1,3))) | Q6: =IF($B6="","",COUNTA(INDEX('Grille AE'!$G$16:$BN$25,1,3):INDEX('Grille AE'!$G$16:$BN$25,10,3))+COUNTA(INDEX('Grille AE'!$G$27:$BN$41,1,3):INDEX('Grille AE'!$G$27:$BN$41,15,3))) | R6: =IF(NOT(ISNUMBER($Q6)),"",$Q6/25) | S6: =IF(NOT(ISNUMBER($R6)),"",IF($R6>='KPI Agents'!$F$5,"Oui","Non")) | T6: =IF(NOT(ISNUMBER($A6)),"",MONTH($A6))
A7: =IF(OR(INDEX('Grille AE'!$G$3:$BN$3,1,4)="",INDEX('Grille AE'!$G$5:$BN$5,1,4)=""),"",INDEX('Grille AE'!$G$5:$BN$5,1,4)) | B7: =IFERROR(IF(INDEX('Grille AE'!$G$3:$BN$3,1,4)="","",INDEX('Grille AE'!$G$3:$BN$3,1,4)),"") | C7: =IF($B7="","",IFERROR(INDEX('Grille AE'!$G$4:$BN$4,1,4),"")) | D7: =IF($B7="","","AE") | E7: =IF($B7="","",IF(INDEX('Grille AE'!$G$10:$BN$10,1,4)="","",INDEX('Grille AE'!$G$10:$BN$10,1,4))) | F7: =IF($B7="","",IF(OR(INDEX('Grille AE'!$G$6:$BN$6,1,4)="",INDEX('Grille AE'!$G$7:$BN$7,1,4)=""),"",ROUND(MOD(INDEX('Grille AE'!$G$7:$BN$7,1,4)-INDEX('Grille AE'!$G$6:$BN$6,1,4),1)*1440,0))) | G7: =IF($B7="","",IFERROR(INDEX('Grille AE'!$G$44:$BN$44,1,4),"")) | H7: =IF($B7="","",IFERROR(INDEX('Grille AE'!$G$45:$BN$45,1,4),"")) | I7: =IF($B7="","",IFERROR(INDEX('Grille AE'!$G$46:$BN$46,1,4),"")) | J7: =IF(NOT(ISNUMBER($I7)),"",IF($I7>='KPI Agents'!$E$5,"Objectif Atteint","Non Atteint")) | K7: =IF(NOT(ISNUMBER($A7)),"",_xlfn.ISOWEEKNUM($A7)) | L7: =IF(NOT(ISNUMBER($A7)),"",YEAR($A7)) | M7: =IF($B7="","","Grille AE") | N7: =IF($B7="","",SUBSTITUTE(ADDRESS(1,6+4,4),"1","")) | O7: =IF($B7="","",IF(INDEX('Grille AE'!$G$9:$BN$9,1,4)="","",INDEX('Grille AE'!$G$9:$BN$9,1,4))) | P7: =IF($B7="","",IF(INDEX('Grille AE'!$G$8:$BN$8,1,4)="","",INDEX('Grille AE'!$G$8:$BN$8,1,4))) | Q7: =IF($B7="","",COUNTA(INDEX('Grille AE'!$G$16:$BN$25,1,4):INDEX('Grille AE'!$G$16:$BN$25,10,4))+COUNTA(INDEX('Grille AE'!$G$27:$BN$41,1,4):INDEX('Grille AE'!$G$27:$BN$41,15,4))) | R7: =IF(NOT(ISNUMBER($Q7)),"",$Q7/25) | S7: =IF(NOT(ISNUMBER($R7)),"",IF($R7>='KPI Agents'!$F$5,"Oui","Non")) | T7: =IF(NOT(ISNUMBER($A7)),"",MONTH($A7))
A8: =IF(OR(INDEX('Grille AE'!$G$3:$BN$3,1,5)="",INDEX('Grille AE'!$G$5:$BN$5,1,5)=""),"",INDEX('Grille AE'!$G$5:$BN$5,1,5)) | B8: =IFERROR(IF(INDEX('Grille AE'!$G$3:$BN$3,1,5)="","",INDEX('Grille AE'!$G$3:$BN$3,1,5)),"") | C8: =IF($B8="","",IFERROR(INDEX('Grille AE'!$G$4:$BN$4,1,5),"")) | D8: =IF($B8="","","AE") | E8: =IF($B8="","",IF(INDEX('Grille AE'!$G$10:$BN$10,1,5)="","",INDEX('Grille AE'!$G$10:$BN$10,1,5))) | F8: =IF($B8="","",IF(OR(INDEX('Grille AE'!$G$6:$BN$6,1,5)="",INDEX('Grille AE'!$G$7:$BN$7,1,5)=""),"",ROUND(MOD(INDEX('Grille AE'!$G$7:$BN$7,1,5)-INDEX('Grille AE'!$G$6:$BN$6,1,5),1)*1440,0))) | G8: =IF($B8="","",IFERROR(INDEX('Grille AE'!$G$44:$BN$44,1,5),"")) | H8: =IF($B8="","",IFERROR(INDEX('Grille AE'!$G$45:$BN$45,1,5),"")) | I8: =IF($B8="","",IFERROR(INDEX('Grille AE'!$G$46:$BN$46,1,5),"")) | J8: =IF(NOT(ISNUMBER($I8)),"",IF($I8>='KPI Agents'!$E$5,"Objectif Atteint","Non Atteint")) | K8: =IF(NOT(ISNUMBER($A8)),"",_xlfn.ISOWEEKNUM($A8)) | L8: =IF(NOT(ISNUMBER($A8)),"",YEAR($A8)) | M8: =IF($B8="","","Grille AE") | N8: =IF($B8="","",SUBSTITUTE(ADDRESS(1,6+5,4),"1","")) | O8: =IF($B8="","",IF(INDEX('Grille AE'!$G$9:$BN$9,1,5)="","",INDEX('Grille AE'!$G$9:$BN$9,1,5))) | P8: =IF($B8="","",IF(INDEX('Grille AE'!$G$8:$BN$8,1,5)="","",INDEX('Grille AE'!$G$8:$BN$8,1,5))) | Q8: =IF($B8="","",COUNTA(INDEX('Grille AE'!$G$16:$BN$25,1,5):INDEX('Grille AE'!$G$16:$BN$25,10,5))+COUNTA(INDEX('Grille AE'!$G$27:$BN$41,1,5):INDEX('Grille AE'!$G$27:$BN$41,15,5))) | R8: =IF(NOT(ISNUMBER($Q8)),"",$Q8/25) | S8: =IF(NOT(ISNUMBER($R8)),"",IF($R8>='KPI Agents'!$F$5,"Oui","Non")) | T8: =IF(NOT(ISNUMBER($A8)),"",MONTH($A8))
A9: =IF(OR(INDEX('Grille AE'!$G$3:$BN$3,1,6)="",INDEX('Grille AE'!$G$5:$BN$5,1,6)=""),"",INDEX('Grille AE'!$G$5:$BN$5,1,6)) | B9: =IFERROR(IF(INDEX('Grille AE'!$G$3:$BN$3,1,6)="","",INDEX('Grille AE'!$G$3:$BN$3,1,6)),"") | C9: =IF($B9="","",IFERROR(INDEX('Grille AE'!$G$4:$BN$4,1,6),"")) | D9: =IF($B9="","","AE") | E9: =IF($B9="","",IF(INDEX('Grille AE'!$G$10:$BN$10,1,6)="","",INDEX('Grille AE'!$G$10:$BN$10,1,6))) | F9: =IF($B9="","",IF(OR(INDEX('Grille AE'!$G$6:$BN$6,1,6)="",INDEX('Grille AE'!$G$7:$BN$7,1,6)=""),"",ROUND(MOD(INDEX('Grille AE'!$G$7:$BN$7,1,6)-INDEX('Grille AE'!$G$6:$BN$6,1,6),1)*1440,0))) | G9: =IF($B9="","",IFERROR(INDEX('Grille AE'!$G$44:$BN$44,1,6),"")) | H9: =IF($B9="","",IFERROR(INDEX('Grille AE'!$G$45:$BN$45,1,6),"")) | I9: =IF($B9="","",IFERROR(INDEX('Grille AE'!$G$46:$BN$46,1,6),"")) | J9: =IF(NOT(ISNUMBER($I9)),"",IF($I9>='KPI Agents'!$E$5,"Objectif Atteint","Non Atteint")) | K9: =IF(NOT(ISNUMBER($A9)),"",_xlfn.ISOWEEKNUM($A9)) | L9: =IF(NOT(ISNUMBER($A9)),"",YEAR($A9)) | M9: =IF($B9="","","Grille AE") | N9: =IF($B9="","",SUBSTITUTE(ADDRESS(1,6+6,4),"1","")) | O9: =IF($B9="","",IF(INDEX('Grille AE'!$G$9:$BN$9,1,6)="","",INDEX('Grille AE'!$G$9:$BN$9,1,6))) | P9: =IF($B9="","",IF(INDEX('Grille AE'!$G$8:$BN$8,1,6)="","",INDEX('Grille AE'!$G$8:$BN$8,1,6))) | Q9: =IF($B9="","",COUNTA(INDEX('Grille AE'!$G$16:$BN$25,1,6):INDEX('Grille AE'!$G$16:$BN$25,10,6))+COUNTA(INDEX('Grille AE'!$G$27:$BN$41,1,6):INDEX('Grille AE'!$G$27:$BN$41,15,6))) | R9: =IF(NOT(ISNUMBER($Q9)),"",$Q9/25) | S9: =IF(NOT(ISNUMBER($R9)),"",IF($R9>='KPI Agents'!$F$5,"Oui","Non")) | T9: =IF(NOT(ISNUMBER($A9)),"",MONTH($A9))
A10: =IF(OR(INDEX('Grille AE'!$G$3:$BN$3,1,7)="",INDEX('Grille AE'!$G$5:$BN$5,1,7)=""),"",INDEX('Grille AE'!$G$5:$BN$5,1,7)) | B10: =IFERROR(IF(INDEX('Grille AE'!$G$3:$BN$3,1,7)="","",INDEX('Grille AE'!$G$3:$BN$3,1,7)),"") | C10: =IF($B10="","",IFERROR(INDEX('Grille AE'!$G$4:$BN$4,1,7),"")) | D10: =IF($B10="","","AE") | E10: =IF($B10="","",IF(INDEX('Grille AE'!$G$10:$BN$10,1,7)="","",INDEX('Grille AE'!$G$10:$BN$10,1,7))) | F10: =IF($B10="","",IF(OR(INDEX('Grille AE'!$G$6:$BN$6,1,7)="",INDEX('Grille AE'!$G$7:$BN$7,1,7)=""),"",ROUND(MOD(INDEX('Grille AE'!$G$7:$BN$7,1,7)-INDEX('Grille AE'!$G$6:$BN$6,1,7),1)*1440,0))) | G10: =IF($B10="","",IFERROR(INDEX('Grille AE'!$G$44:$BN$44,1,7),"")) | H10: =IF($B10="","",IFERROR(INDEX('Grille AE'!$G$45:$BN$45,1,7),"")) | I10: =IF($B10="","",IFERROR(INDEX('Grille AE'!$G$46:$BN$46,1,7),"")) | J10: =IF(NOT(ISNUMBER($I10)),"",IF($I10>='KPI Agents'!$E$5,"Objectif Atteint","Non Atteint")) | K10: =IF(NOT(ISNUMBER($A10)),"",_xlfn.ISOWEEKNUM($A10)) | L10: =IF(NOT(ISNUMBER($A10)),"",YEAR($A10)) | M10: =IF($B10="","","Grille AE") | N10: =IF($B10="","",SUBSTITUTE(ADDRESS(1,6+7,4),"1","")) | O10: =IF($B10="","",IF(INDEX('Grille AE'!$G$9:$BN$9,1,7)="","",INDEX('Grille AE'!$G$9:$BN$9,1,7))) | P10: =IF($B10="","",IF(INDEX('Grille AE'!$G$8:$BN$8,1,7)="","",INDEX('Grille AE'!$G$8:$BN$8,1,7))) | Q10: =IF($B10="","",COUNTA(INDEX('Grille AE'!$G$16:$BN$25,1,7):INDEX('Grille AE'!$G$16:$BN$25,10,7))+COUNTA(INDEX('Grille AE'!$G$27:$BN$41,1,7):INDEX('Grille AE'!$G$27:$BN$41,15,7))) | R10: =IF(NOT(ISNUMBER($Q10)),"",$Q10/25) | S10: =IF(NOT(ISNUMBER($R10)),"",IF($R10>='KPI Agents'!$F$5,"Oui","Non")) | T10: =IF(NOT(ISNUMBER($A10)),"",MONTH($A10))
A11: =IF(OR(INDEX('Grille AE'!$G$3:$BN$3,1,8)="",INDEX('Grille AE'!$G$5:$BN$5,1,8)=""),"",INDEX('Grille AE'!$G$5:$BN$5,1,8)) | B11: =IFERROR(IF(INDEX('Grille AE'!$G$3:$BN$3,1,8)="","",INDEX('Grille AE'!$G$3:$BN$3,1,8)),"") | C11: =IF($B11="","",IFERROR(INDEX('Grille AE'!$G$4:$BN$4,1,8),"")) | D11: =IF($B11="","","AE") | E11: =IF($B11="","",IF(INDEX('Grille AE'!$G$10:$BN$10,1,8)="","",INDEX('Grille AE'!$G$10:$BN$10,1,8))) | F11: =IF($B11="","",IF(OR(INDEX('Grille AE'!$G$6:$BN$6,1,8)="",INDEX('Grille AE'!$G$7:$BN$7,1,8)=""),"",ROUND(MOD(INDEX('Grille AE'!$G$7:$BN$7,1,8)-INDEX('Grille AE'!$G$6:$BN$6,1,8),1)*1440,0))) | G11: =IF($B11="","",IFERROR(INDEX('Grille AE'!$G$44:$BN$44,1,8),"")) | H11: =IF($B11="","",IFERROR(INDEX('Grille AE'!$G$45:$BN$45,1,8),"")) | I11: =IF($B11="","",IFERROR(INDEX('Grille AE'!$G$46:$BN$46,1,8),"")) | J11: =IF(NOT(ISNUMBER($I11)),"",IF($I11>='KPI Agents'!$E$5,"Objectif Atteint","Non Atteint")) | K11: =IF(NOT(ISNUMBER($A11)),"",_xlfn.ISOWEEKNUM($A11)) | L11: =IF(NOT(ISNUMBER($A11)),"",YEAR($A11)) | M11: =IF($B11="","","Grille AE") | N11: =IF($B11="","",SUBSTITUTE(ADDRESS(1,6+8,4),"1","")) | O11: =IF($B11="","",IF(INDEX('Grille AE'!$G$9:$BN$9,1,8)="","",INDEX('Grille AE'!$G$9:$BN$9,1,8))) | P11: =IF($B11="","",IF(INDEX('Grille AE'!$G$8:$BN$8,1,8)="","",INDEX('Grille AE'!$G$8:$BN$8,1,8))) | Q11: =IF($B11="","",COUNTA(INDEX('Grille AE'!$G$16:$BN$25,1,8):INDEX('Grille AE'!$G$16:$BN$25,10,8))+COUNTA(INDEX('Grille AE'!$G$27:$BN$41,1,8):INDEX('Grille AE'!$G$27:$BN$41,15,8))) | R11: =IF(NOT(ISNUMBER($Q11)),"",$Q11/25) | S11: =IF(NOT(ISNUMBER($R11)),"",IF($R11>='KPI Agents'!$F$5,"Oui","Non")) | T11: =IF(NOT(ISNUMBER($A11)),"",MONTH($A11))
A12: =IF(OR(INDEX('Grille AE'!$G$3:$BN$3,1,9)="",INDEX('Grille AE'!$G$5:$BN$5,1,9)=""),"",INDEX('Grille AE'!$G$5:$BN$5,1,9)) | B12: =IFERROR(IF(INDEX('Grille AE'!$G$3:$BN$3,1,9)="","",INDEX('Grille AE'!$G$3:$BN$3,1,9)),"") | C12: =IF($B12="","",IFERROR(INDEX('Grille AE'!$G$4:$BN$4,1,9),"")) | D12: =IF($B12="","","AE") | E12: =IF($B12="","",IF(INDEX('Grille AE'!$G$10:$BN$10,1,9)="","",INDEX('Grille AE'!$G$10:$BN$10,1,9))) | F12: =IF($B12="","",IF(OR(INDEX('Grille AE'!$G$6:$BN$6,1,9)="",INDEX('Grille AE'!$G$7:$BN$7,1,9)=""),"",ROUND(MOD(INDEX('Grille AE'!$G$7:$BN$7,1,9)-INDEX('Grille AE'!$G$6:$BN$6,1,9),1)*1440,0))) | G12: =IF($B12="","",IFERROR(INDEX('Grille AE'!$G$44:$BN$44,1,9),"")) | H12: =IF($B12="","",IFERROR(INDEX('Grille AE'!$G$45:$BN$45,1,9),"")) | I12: =IF($B12="","",IFERROR(INDEX('Grille AE'!$G$46:$BN$46,1,9),"")) | J12: =IF(NOT(ISNUMBER($I12)),"",IF($I12>='KPI Agents'!$E$5,"Objectif Atteint","Non Atteint")) | K12: =IF(NOT(ISNUMBER($A12)),"",_xlfn.ISOWEEKNUM($A12)) | L12: =IF(NOT(ISNUMBER($A12)),"",YEAR($A12)) | M12: =IF($B12="","","Grille AE") | N12: =IF($B12="","",SUBSTITUTE(ADDRESS(1,6+9,4),"1","")) | O12: =IF($B12="","",IF(INDEX('Grille AE'!$G$9:$BN$9,1,9)="","",INDEX('Grille AE'!$G$9:$BN$9,1,9))) | P12: =IF($B12="","",IF(INDEX('Grille AE'!$G$8:$BN$8,1,9)="","",INDEX('Grille AE'!$G$8:$BN$8,1,9))) | Q12: =IF($B12="","",COUNTA(INDEX('Grille AE'!$G$16:$BN$25,1,9):INDEX('Grille AE'!$G$16:$BN$25,10,9))+COUNTA(INDEX('Grille AE'!$G$27:$BN$41,1,9):INDEX('Grille AE'!$G$27:$BN$41,15,9))) | R12: =IF(NOT(ISNUMBER($Q12)),"",$Q12/25) | S12: =IF(NOT(ISNUMBER($R12)),"",IF($R12>='KPI Agents'!$F$5,"Oui","Non")) | T12: =IF(NOT(ISNUMBER($A12)),"",MONTH($A12))
A13: =IF(OR(INDEX('Grille AE'!$G$3:$BN$3,1,10)="",INDEX('Grille AE'!$G$5:$BN$5,1,10)=""),"",INDEX('Grille AE'!$G$5:$BN$5,1,10)) | B13: =IFERROR(IF(INDEX('Grille AE'!$G$3:$BN$3,1,10)="","",INDEX('Grille AE'!$G$3:$BN$3,1,10)),"") | C13: =IF($B13="","",IFERROR(INDEX('Grille AE'!$G$4:$BN$4,1,10),"")) | D13: =IF($B13="","","AE") | E13: =IF($B13="","",IF(INDEX('Grille AE'!$G$10:$BN$10,1,10)="","",INDEX('Grille AE'!$G$10:$BN$10,1,10))) | F13: =IF($B13="","",IF(OR(INDEX('Grille AE'!$G$6:$BN$6,1,10)="",INDEX('Grille AE'!$G$7:$BN$7,1,10)=""),"",ROUND(MOD(INDEX('Grille AE'!$G$7:$BN$7,1,10)-INDEX('Grille AE'!$G$6:$BN$6,1,10),1)*1440,0))) | G13: =IF($B13="","",IFERROR(INDEX('Grille AE'!$G$44:$BN$44,1,10),"")) | H13: =IF($B13="","",IFERROR(INDEX('Grille AE'!$G$45:$BN$45,1,10),"")) | I13: =IF($B13="","",IFERROR(INDEX('Grille AE'!$G$46:$BN$46,1,10),"")) | J13: =IF(NOT(ISNUMBER($I13)),"",IF($I13>='KPI Agents'!$E$5,"Objectif Atteint","Non Atteint")) | K13: =IF(NOT(ISNUMBER($A13)),"",_xlfn.ISOWEEKNUM($A13)) | L13: =IF(NOT(ISNUMBER($A13)),"",YEAR($A13)) | M13: =IF($B13="","","Grille AE") | N13: =IF($B13="","",SUBSTITUTE(ADDRESS(1,6+10,4),"1","")) | O13: =IF($B13="","",IF(INDEX('Grille AE'!$G$9:$BN$9,1,10)="","",INDEX('Grille AE'!$G$9:$BN$9,1,10))) | P13: =IF($B13="","",IF(INDEX('Grille AE'!$G$8:$BN$8,1,10)="","",INDEX('Grille AE'!$G$8:$BN$8,1,10))) | Q13: =IF($B13="","",COUNTA(INDEX('Grille AE'!$G$16:$BN$25,1,10):INDEX('Grille AE'!$G$16:$BN$25,10,10))+COUNTA(INDEX('Grille AE'!$G$27:$BN$41,1,10):INDEX('Grille AE'!$G$27:$BN$41,15,10))) | R13: =IF(NOT(ISNUMBER($Q13)),"",$Q13/25) | S13: =IF(NOT(ISNUMBER($R13)),"",IF($R13>='KPI Agents'!$F$5,"Oui","Non")) | T13: =IF(NOT(ISNUMBER($A13)),"",MONTH($A13))
A14: =IF(OR(INDEX('Grille AE'!$G$3:$BN$3,1,11)="",INDEX('Grille AE'!$G$5:$BN$5,1,11)=""),"",INDEX('Grille AE'!$G$5:$BN$5,1,11)) | B14: =IFERROR(IF(INDEX('Grille AE'!$G$3:$BN$3,1,11)="","",INDEX('Grille AE'!$G$3:$BN$3,1,11)),"") | C14: =IF($B14="","",IFERROR(INDEX('Grille AE'!$G$4:$BN$4,1,11),"")) | D14: =IF($B14="","","AE") | E14: =IF($B14="","",IF(INDEX('Grille AE'!$G$10:$BN$10,1,11)="","",INDEX('Grille AE'!$G$10:$BN$10,1,11))) | F14: =IF($B14="","",IF(OR(INDEX('Grille AE'!$G$6:$BN$6,1,11)="",INDEX('Grille AE'!$G$7:$BN$7,1,11)=""),"",ROUND(MOD(INDEX('Grille AE'!$G$7:$BN$7,1,11)-INDEX('Grille AE'!$G$6:$BN$6,1,11),1)*1440,0))) | G14: =IF($B14="","",IFERROR(INDEX('Grille AE'!$G$44:$BN$44,1,11),"")) | H14: =IF($B14="","",IFERROR(INDEX('Grille AE'!$G$45:$BN$45,1,11),"")) | I14: =IF($B14="","",IFERROR(INDEX('Grille AE'!$G$46:$BN$46,1,11),"")) | J14: =IF(NOT(ISNUMBER($I14)),"",IF($I14>='KPI Agents'!$E$5,"Objectif Atteint","Non Atteint")) | K14: =IF(NOT(ISNUMBER($A14)),"",_xlfn.ISOWEEKNUM($A14)) | L14: =IF(NOT(ISNUMBER($A14)),"",YEAR($A14)) | M14: =IF($B14="","","Grille AE") | N14: =IF($B14="","",SUBSTITUTE(ADDRESS(1,6+11,4),"1","")) | O14: =IF($B14="","",IF(INDEX('Grille AE'!$G$9:$BN$9,1,11)="","",INDEX('Grille AE'!$G$9:$BN$9,1,11))) | P14: =IF($B14="","",IF(INDEX('Grille AE'!$G$8:$BN$8,1,11)="","",INDEX('Grille AE'!$G$8:$BN$8,1,11))) | Q14: =IF($B14="","",COUNTA(INDEX('Grille AE'!$G$16:$BN$25,1,11):INDEX('Grille AE'!$G$16:$BN$25,10,11))+COUNTA(INDEX('Grille AE'!$G$27:$BN$41,1,11):INDEX('Grille AE'!$G$27:$BN$41,15,11))) | R14: =IF(NOT(ISNUMBER($Q14)),"",$Q14/25) | S14: =IF(NOT(ISNUMBER($R14)),"",IF($R14>='KPI Agents'!$F$5,"Oui","Non")) | T14: =IF(NOT(ISNUMBER($A14)),"",MONTH($A14))
A15: =IF(OR(INDEX('Grille AE'!$G$3:$BN$3,1,12)="",INDEX('Grille AE'!$G$5:$BN$5,1,12)=""),"",INDEX('Grille AE'!$G$5:$BN$5,1,12)) | B15: =IFERROR(IF(INDEX('Grille AE'!$G$3:$BN$3,1,12)="","",INDEX('Grille AE'!$G$3:$BN$3,1,12)),"") | C15: =IF($B15="","",IFERROR(INDEX('Grille AE'!$G$4:$BN$4,1,12),"")) | D15: =IF($B15="","","AE") | E15: =IF($B15="","",IF(INDEX('Grille AE'!$G$10:$BN$10,1,12)="","",INDEX('Grille AE'!$G$10:$BN$10,1,12))) | F15: =IF($B15="","",IF(OR(INDEX('Grille AE'!$G$6:$BN$6,1,12)="",INDEX('Grille AE'!$G$7:$BN$7,1,12)=""),"",ROUND(MOD(INDEX('Grille AE'!$G$7:$BN$7,1,12)-INDEX('Grille AE'!$G$6:$BN$6,1,12),1)*1440,0))) | G15: =IF($B15="","",IFERROR(INDEX('Grille AE'!$G$44:$BN$44,1,12),"")) | H15: =IF($B15="","",IFERROR(INDEX('Grille AE'!$G$45:$BN$45,1,12),"")) | I15: =IF($B15="","",IFERROR(INDEX('Grille AE'!$G$46:$BN$46,1,12),"")) | J15: =IF(NOT(ISNUMBER($I15)),"",IF($I15>='KPI Agents'!$E$5,"Objectif Atteint","Non Atteint")) | K15: =IF(NOT(ISNUMBER($A15)),"",_xlfn.ISOWEEKNUM($A15)) | L15: =IF(NOT(ISNUMBER($A15)),"",YEAR($A15)) | M15: =IF($B15="","","Grille AE") | N15: =IF($B15="","",SUBSTITUTE(ADDRESS(1,6+12,4),"1","")) | O15: =IF($B15="","",IF(INDEX('Grille AE'!$G$9:$BN$9,1,12)="","",INDEX('Grille AE'!$G$9:$BN$9,1,12))) | P15: =IF($B15="","",IF(INDEX('Grille AE'!$G$8:$BN$8,1,12)="","",INDEX('Grille AE'!$G$8:$BN$8,1,12))) | Q15: =IF($B15="","",COUNTA(INDEX('Grille AE'!$G$16:$BN$25,1,12):INDEX('Grille AE'!$G$16:$BN$25,10,12))+COUNTA(INDEX('Grille AE'!$G$27:$BN$41,1,12):INDEX('Grille AE'!$G$27:$BN$41,15,12))) | R15: =IF(NOT(ISNUMBER($Q15)),"",$Q15/25) | S15: =IF(NOT(ISNUMBER($R15)),"",IF($R15>='KPI Agents'!$F$5,"Oui","Non")) | T15: =IF(NOT(ISNUMBER($A15)),"",MONTH($A15))
A16: =IF(OR(INDEX('Grille AE'!$G$3:$BN$3,1,13)="",INDEX('Grille AE'!$G$5:$BN$5,1,13)=""),"",INDEX('Grille AE'!$G$5:$BN$5,1,13)) | B16: =IFERROR(IF(INDEX('Grille AE'!$G$3:$BN$3,1,13)="","",INDEX('Grille AE'!$G$3:$BN$3,1,13)),"") | C16: =IF($B16="","",IFERROR(INDEX('Grille AE'!$G$4:$BN$4,1,13),"")) | D16: =IF($B16="","","AE") | E16: =IF($B16="","",IF(INDEX('Grille AE'!$G$10:$BN$10,1,13)="","",INDEX('Grille AE'!$G$10:$BN$10,1,13))) | F16: =IF($B16="","",IF(OR(INDEX('Grille AE'!$G$6:$BN$6,1,13)="",INDEX('Grille AE'!$G$7:$BN$7,1,13)=""),"",ROUND(MOD(INDEX('Grille AE'!$G$7:$BN$7,1,13)-INDEX('Grille AE'!$G$6:$BN$6,1,13),1)*1440,0))) | G16: =IF($B16="","",IFERROR(INDEX('Grille AE'!$G$44:$BN$44,1,13),"")) | H16: =IF($B16="","",IFERROR(INDEX('Grille AE'!$G$45:$BN$45,1,13),"")) | I16: =IF($B16="","",IFERROR(INDEX('Grille AE'!$G$46:$BN$46,1,13),"")) | J16: =IF(NOT(ISNUMBER($I16)),"",IF($I16>='KPI Agents'!$E$5,"Objectif Atteint","Non Atteint")) | K16: =IF(NOT(ISNUMBER($A16)),"",_xlfn.ISOWEEKNUM($A16)) | L16: =IF(NOT(ISNUMBER($A16)),"",YEAR($A16)) | M16: =IF($B16="","","Grille AE") | N16: =IF($B16="","",SUBSTITUTE(ADDRESS(1,6+13,4),"1","")) | O16: =IF($B16="","",IF(INDEX('Grille AE'!$G$9:$BN$9,1,13)="","",INDEX('Grille AE'!$G$9:$BN$9,1,13))) | P16: =IF($B16="","",IF(INDEX('Grille AE'!$G$8:$BN$8,1,13)="","",INDEX('Grille AE'!$G$8:$BN$8,1,13))) | Q16: =IF($B16="","",COUNTA(INDEX('Grille AE'!$G$16:$BN$25,1,13):INDEX('Grille AE'!$G$16:$BN$25,10,13))+COUNTA(INDEX('Grille AE'!$G$27:$BN$41,1,13):INDEX('Grille AE'!$G$27:$BN$41,15,13))) | R16: =IF(NOT(ISNUMBER($Q16)),"",$Q16/25) | S16: =IF(NOT(ISNUMBER($R16)),"",IF($R16>='KPI Agents'!$F$5,"Oui","Non")) | T16: =IF(NOT(ISNUMBER($A16)),"",MONTH($A16))
A17: =IF(OR(INDEX('Grille AE'!$G$3:$BN$3,1,14)="",INDEX('Grille AE'!$G$5:$BN$5,1,14)=""),"",INDEX('Grille AE'!$G$5:$BN$5,1,14)) | B17: =IFERROR(IF(INDEX('Grille AE'!$G$3:$BN$3,1,14)="","",INDEX('Grille AE'!$G$3:$BN$3,1,14)),"") | C17: =IF($B17="","",IFERROR(INDEX('Grille AE'!$G$4:$BN$4,1,14),"")) | D17: =IF($B17="","","AE") | E17: =IF($B17="","",IF(INDEX('Grille AE'!$G$10:$BN$10,1,14)="","",INDEX('Grille AE'!$G$10:$BN$10,1,14))) | F17: =IF($B17="","",IF(OR(INDEX('Grille AE'!$G$6:$BN$6,1,14)="",INDEX('Grille AE'!$G$7:$BN$7,1,14)=""),"",ROUND(MOD(INDEX('Grille AE'!$G$7:$BN$7,1,14)-INDEX('Grille AE'!$G$6:$BN$6,1,14),1)*1440,0))) | G17: =IF($B17="","",IFERROR(INDEX('Grille AE'!$G$44:$BN$44,1,14),"")) | H17: =IF($B17="","",IFERROR(INDEX('Grille AE'!$G$45:$BN$45,1,14),"")) | I17: =IF($B17="","",IFERROR(INDEX('Grille AE'!$G$46:$BN$46,1,14),"")) | J17: =IF(NOT(ISNUMBER($I17)),"",IF($I17>='KPI Agents'!$E$5,"Objectif Atteint","Non Atteint")) | K17: =IF(NOT(ISNUMBER($A17)),"",_xlfn.ISOWEEKNUM($A17)) | L17: =IF(NOT(ISNUMBER($A17)),"",YEAR($A17)) | M17: =IF($B17="","","Grille AE") | N17: =IF($B17="","",SUBSTITUTE(ADDRESS(1,6+14,4),"1","")) | O17: =IF($B17="","",IF(INDEX('Grille AE'!$G$9:$BN$9,1,14)="","",INDEX('Grille AE'!$G$9:$BN$9,1,14))) | P17: =IF($B17="","",IF(INDEX('Grille AE'!$G$8:$BN$8,1,14)="","",INDEX('Grille AE'!$G$8:$BN$8,1,14))) | Q17: =IF($B17="","",COUNTA(INDEX('Grille AE'!$G$16:$BN$25,1,14):INDEX('Grille AE'!$G$16:$BN$25,10,14))+COUNTA(INDEX('Grille AE'!$G$27:$BN$41,1,14):INDEX('Grille AE'!$G$27:$BN$41,15,14))) | R17: =IF(NOT(ISNUMBER($Q17)),"",$Q17/25) | S17: =IF(NOT(ISNUMBER($R17)),"",IF($R17>='KPI Agents'!$F$5,"Oui","Non")) | T17: =IF(NOT(ISNUMBER($A17)),"",MONTH($A17))
